Workbook
Name MonthlyLoanPayment: #REF!
Name LoanAmount: #REF!
Name InterestRate: #REF!
Name total_payments: #REF!
Name DurationOfLoan: #REF!
Name StartTime: #REF!
Name total_loan_payment: #REF!
Name LoanStart: #REF!
Name interest: #REF!
Name PropertyTaxAmount: #REF!

Sheet PMI
A1: Date | B1: PMI | C1: PMI New Orders | D1: PMI Production | E1: PMI Employment | F1: PMI Supplier Deliveries | G1: PMI Inventories | H1: PMI Customers Inventories | I1: PMI Prices | J1: PMI Backlog of Orders | K1: PMI New Export Orders | L1: PMI Imports | M1: PMI Consumption | N1: PMI Inputs
A2: 17533 | B2: 51.7 | C2: 53.3 | D2: 59.1 | E2: 54.8 | F2: 36.3 | M2: =(PMI!$D2+PMI!$E2)/2 -> 56.95
A3: 17564 | B3: 50.2 | C3: 51.1 | D3: 55.2 | E3: 55.8 | F3: 37.1 | G3: 45.3 | M3: =(PMI!$D3+PMI!$E3)/2 -> 55.5
A4: 17593 | B4: 43.3 | C4: 43.9 | D4: 47.8 | E4: 44 | F4: 32.7 | G4: 43.9 | I4: 69.3 | M4: =(PMI!$D4+PMI!$E4)/2 -> 45.9
A5: 17624 | B5: 45.4 | C5: 44.5 | D5: 49.5 | E5: 43.9 | F5: 41.6 | G5: 44.5 | I5: 75.8 | M5: =(PMI!$D5+PMI!$E5)/2 -> 46.7
A6: 17654 | B6: 49.5 | C6: 51.2 | D6: 52.1 | E6: 51.8 | F6: 40.4 | G6: 46.1 | I6: 70.8 | M6: =(PMI!$D6+PMI!$E6)/2 -> 51.95
A7: 17685 | B7: 53 | C7: 58.1 | D7: 56.8 | E7: 50.8 | F7: 38.4 | G7: 47 | I7: 78.5 | M7: =(PMI!$D7+PMI!$E7)/2 -> 53.8
A8: 17715 | B8: 48.4 | C8: 50.4 | D8: 51.4 | E8: 49.1 | F8: 36.8 | G8: 54.7 | I8: 77.3 | M8: =(PMI!$D8+PMI!$E8)/2 -> 50.25
A9: 17746 | B9: 45.1 | C9: 46 | D9: 51 | E9: 46.1 | F9: 31.2 | G9: 51.1 | I9: 77 | M9: =(PMI!$D9+PMI!$E9)/2 -> 48.55
A10: 17777 | B10: 42.1 | C10: 40.6 | D10: 47.9 | E10: 46.1 | F10: 28.3 | G10: 46.6 | I10: 66 | M10: =(PMI!$D10+PMI!$E10)/2 -> 47
A11: 17807 | B11: 47.2 | C11: 52.1 | D11: 52.7 | E11: 47.5 | F11: 28.7 | G11: 45.2 | I11: 56.6 | M11: =(PMI!$D11+PMI!$E11)/2 -> 50.1
A12: 17838 | B12: 42.4 | C12: 43.2 | D12: 48.9 | E12: 44 | F12: 28 | G12: 45.4 | I12: 51 | M12: =(PMI!$D12+PMI!$E12)/2 -> 46.45
A13: 17868 | B13: 35 | C13: 34.5 | D13: 42.1 | E13: 39 | F13: 17.7 | G13: 42.6 | I13: 47.5 | M13: =(PMI!$D13+PMI!$E13)/2 -> 40.55
A14: 17899 | B14: 32.9 | C14: 31.4 | D14: 42 | E14: 34.1 | F14: 16.6 | G14: 37 | I14: 39.6 | M14: =(PMI!$D14+PMI!$E14)/2 -> 38.05
A15: 17930 | B15: 31.3 | C15: 34.2 | D15: 39.6 | E15: 28.3 | F15: 13.1 | G15: 36.6 | I15: 31.3 | M15: =(PMI!$D15+PMI!$E15)/2 -> 33.95
... A483: 32174 | B483: 56.2 | C483: 57 | D483: 58.6 | E483: 52.5 | F483: 61.2 | G483: 48.1 | I483: 81.2 | M483: =(PMI!$D483+PMI!$E483)/2 -> 55.55
A484: 32203 | B484: 54.6 | C484: 57.9 | D484: 57.7 | E484: 50.2 | F484: 57.3 | G484: 41.9 | I484: 74.5 | K484: 64.5 | M484: =(PMI!$D484+PMI!$E484)/2 -> 53.95
A485: 32234 | B485: 55.8 | C485: 57.6 | D485: 59.1 | E485: 49.2 | F485: 58.6 | G485: 51 | I485: 81 | K485: 64 | M485: =(PMI!$D485+PMI!$E485)/2 -> 54.15
A486: 32264 | B486: 55.5 | C486: 57.7 | D486: 58 | E486: 50.4 | F486: 56.9 | G486: 51.2 | I486: 81.5 | K486: 65.5 | M486: =(PMI!$D486+PMI!$E486)/2 -> 54.2
A487: 32295 | B487: 59.3 | C487: 63.6 | D487: 61.7 | E487: 50.5 | F487: 65.6 | G487: 48.2 | I487: 80.7 | K487: 66 | M487: =(PMI!$D487+PMI!$E487)/2 -> 56.1
A488: 32325 | B488: 58.2 | C488: 60.6 | D488: 61.2 | E488: 52.5 | F488: 58.4 | G488: 54.5 | I488: 81 | K488: 67.5 | M488: =(PMI!$D488+PMI!$E488)/2 -> 56.85
A489: 32356 | B489: 56 | C489: 59.2 | D489: 57.8 | E489: 51.2 | F489: 57.4 | G489: 49.4 | I489: 78.2 | K489: 59.9 | M489: =(PMI!$D489+PMI!$E489)/2 -> 54.5
A490: 32387 | B490: 54.5 | C490: 58.6 | D490: 54.8 | E490: 50.2 | F490: 55.2 | G490: 49.5 | I490: 72.8 | K490: 61.7 | M490: =(PMI!$D490+PMI!$E490)/2 -> 52.5
A491: 32417 | B491: 55.4 | C491: 57.2 | D491: 58.7 | E491: 52.4 | F491: 54.8 | G491: 49.2 | I491: 71.5 | K491: 60.8 | M491: =(PMI!$D491+PMI!$E491)/2 -> 55.55
A492: 32448 | B492: 55.6 | C492: 58.4 | D492: 57.5 | E492: 53.8 | F492: 52.1 | G492: 51.6 | I492: 70.9 | K492: 58.1 | M492: =(PMI!$D492+PMI!$E492)/2 -> 55.65
A493: 32478 | B493: 56 | C493: 59 | D493: 57.6 | E493: 54.8 | F493: 53 | G493: 49.9 | I493: 69.8 | K493: 64.3 | M493: =(PMI!$D493+PMI!$E493)/2 -> 56.2
A494: 32509 | B494: 54.7 | C494: 57.3 | D494: 57.9 | E494: 51.4 | F494: 53.9 | G494: 46.7 | I494: 70.5 | K494: 60.1 | M494: =(PMI!$D494+PMI!$E494)/2 -> 54.65
A495: 32540 | B495: 54.1 | C495: 57.3 | D495: 55.6 | E495: 50 | F495: 54 | G495: 49 | I495: 67.9 | K495: 60 | M495: =(PMI!$D495+PMI!$E495)/2 -> 52.8
... A504: 32813 | B504: 46.8 | C504: 49.3 | D504: 49.2 | E504: 45.9 | F504: 42.5 | G504: 41.4 | I504: 40.9 | K504: 56.6 | M504: =(PMI!$D504+PMI!$E504)/2 -> 47.55
A505: 32843 | B505: 47.4 | C505: 50.4 | D505: 49.7 | E505: 44.6 | F505: 43.5 | G505: 43.9 | I505: 41 | K505: 54.9 | L505: 45.5 | M505: =(PMI!$D505+PMI!$E505)/2 -> 47.15 | N505: =(PMI!$F505+PMI!$G505+PMI!$I505+PMI!$L505)/4 -> 43.475
A506: 32874 | B506: 47.2 | C506: 49.1 | D506: 47.4 | E506: 45.4 | F506: 48.2 | G506: 42.7 | I506: 50.8 | K506: 54.3 | L506: 51.8 | M506: =(PMI!$D506+PMI!$E506)/2 -> 46.4 | N506: =(PMI!$F506+PMI!$G506+PMI!$I506+PMI!$L506)/4 -> 48.375
A507: 32905 | B507: 49.1 | C507: 52.5 | D507: 52.8 | E507: 46.5 | F507: 44.4 | G507: 41.4 | I507: 44.6 | K507: 54.7 | L507: 50.3 | M507: =(PMI!$D507+PMI!$E507)/2 -> 49.65 | N507: =(PMI!$F507+PMI!$G507+PMI!$I507+PMI!$L507)/4 -> 45.175
A508: 32933 | B508: 49.9 | C508: 52.3 | D508: 54.7 | E508: 46.5 | F508: 47.2 | G508: 41.2 | I508: 50.1 | K508: 56.3 | L508: 48.7 | M508: =(PMI!$D508+PMI!$E508)/2 -> 50.6 | N508: =(PMI!$F508+PMI!$G508+PMI!$I508+PMI!$L508)/4 -> 46.8
A509: 32964 | B509: 50 | C509: 53.7 | D509: 53.5 | E509: 46.6 | F509: 47.2 | G509: 41.3 | I509: 50.9 | K509: 57.5 | L509: 48 | M509: =(PMI!$D509+PMI!$E509)/2 -> 50.05 | N509: =(PMI!$F509+PMI!$G509+PMI!$I509+PMI!$L509)/4 -> 46.85
A510: 32994 | B510: 49.5 | C510: 51.7 | D510: 53.9 | E510: 46.2 | F510: 48.2 | G510: 40 | I510: 50.1 | K510: 54.3 | L510: 46.5 | M510: =(PMI!$D510+PMI!$E510)/2 -> 50.05 | N510: =(PMI!$F510+PMI!$G510+PMI!$I510+PMI!$L510)/4 -> 46.2
A511: 33025 | B511: 49.2 | C511: 52 | D511: 51.3 | E511: 45.4 | F511: 49.8 | G511: 42.6 | I511: 53.2 | K511: 56 | L511: 47.6 | M511: =(PMI!$D511+PMI!$E511)/2 -> 48.35 | N511: =(PMI!$F511+PMI!$G511+PMI!$I511+PMI!$L511)/4 -> 48.3
A512: 33055 | B512: 46.6 | C512: 46.7 | D512: 49.8 | E512: 46.3 | F512: 46.4 | G512: 39.6 | I512: 51.4 | K512: 57.2 | L512: 47.5 | M512: =(PMI!$D512+PMI!$E512)/2 -> 48.05 | N512: =(PMI!$F512+PMI!$G512+PMI!$I512+PMI!$L512)/4 -> 46.225
A513: 33086 | B513: 46.1 | C513: 45.5 | D513: 47.9 | E513: 43.1 | F513: 50.1 | G513: 43 | I513: 53.1 | K513: 54.6 | L513: 46.9 | M513: =(PMI!$D513+PMI!$E513)/2 -> 45.5 | N513: =(PMI!$F513+PMI!$G513+PMI!$I513+PMI!$L513)/4 -> 48.275
A514: 33117 | B514: 44.5 | C514: 44.9 | D514: 45.5 | E514: 41.3 | F514: 48.9 | G514: 40.8 | I514: 70.2 | K514: 54.7 | L514: 46 | M514: =(PMI!$D514+PMI!$E514)/2 -> 43.4 | N514: =(PMI!$F514+PMI!$G514+PMI!$I514+PMI!$L514)/4 -> 51.475
A515: 33147 | B515: 43.2 | C515: 43.1 | D515: 43.6 | E515: 40.2 | F515: 48.1 | G515: 41.2 | I515: 73.4 | K515: 51.5 | L515: 47.4 | M515: =(PMI!$D515+PMI!$E515)/2 -> 41.9 | N515: =(PMI!$F515+PMI!$G515+PMI!$I515+PMI!$L515)/4 -> 52.525
...

Sheet NPMI
A1: Date | B1: NPMI | C1: NPMI Business Activity | D1: NPMI New Orders | E1: NPMI Employment | F1: NPMI Supplier Deliveries | G1: NPMI Inventories | H1: NPMI Prices | I1: NPMI Backlog of Orders | J1: NPMI New Export Orders | K1: NPMI Imports | L1: NPMI Inventory Sentiment | M1: NPMI Inputs
A2: 35827 | C2: 56.5 | D2: 58.8 | E2: 55 | G2: 49 | H2: 54.9 | I2: 49 | J2: 48.5 | K2: 52.2 | L2: 67 | M2: =(D2+F2+H2)/3 -> 37.9
A3: 35855 | C3: 61.4 | D3: 57.4 | E3: 55 | G3: 48.5 | H3: 52.7 | I3: 49 | J3: 52 | K3: 51.5 | L3: 61.5 | M3: =(D3+F3+H3)/3 -> 36.7
A4: 35886 | C4: 58.9 | D4: 59.1 | E4: 54.8 | G4: 50.5 | H4: 51.6 | I4: 51.5 | J4: 51.5 | K4: 52.6 | L4: 59.5 | M4: =(D4+F4+H4)/3 -> 36.9
A5: 35916 | C5: 57 | D5: 55.1 | E5: 54.1 | G5: 52.5 | H5: 47.9 | I5: 51.5 | J5: 58.5 | K5: 50 | L5: 64 | M5: =(D5+F5+H5)/3 -> 34.333333
A6: 35947 | C6: 58.6 | D6: 57.5 | E6: 51.6 | G6: 52.5 | H6: 46.8 | I6: 51 | J6: 56.5 | K6: 52.1 | L6: 66.5 | M6: =(D6+F6+H6)/3 -> 34.766667
A7: 35977 | C7: 61.2 | D7: 60.2 | E7: 52.8 | G7: 50 | H7: 47.2 | I7: 53 | J7: 48.5 | K7: 52.8 | L7: 63.5 | M7: =(D7+F7+H7)/3 -> 35.8
A8: 36008 | C8: 58.7 | D8: 55.8 | E8: 52.5 | G8: 49.5 | H8: 45.5 | I8: 50 | J8: 55 | K8: 54.5 | L8: 69 | M8: =(D8+F8+H8)/3 -> 33.766667
A9: 36039 | C9: 58.6 | D9: 58.2 | E9: 51.9 | G9: 48 | H9: 47 | I9: 52 | J9: 51.5 | K9: 50.9 | L9: 60.5 | M9: =(D9+F9+H9)/3 -> 35.066667
A10: 36069 | C10: 52.2 | D10: 55.3 | E10: 52.3 | G10: 48 | H10: 47.9 | I10: 56.5 | J10: 54 | K10: 55.2 | L10: 62.5 | M10: =(D10+F10+H10)/3 -> 34.4
A11: 36100 | C11: 57.4 | D11: 55.9 | E11: 53.7 | G11: 50.5 | H11: 46.2 | I11: 54 | J11: 54 | K11: 52 | L11: 65 | M11: =(D11+F11+H11)/3 -> 34.033333
A12: 36130 | C12: 54 | D12: 54.7 | E12: 53.1 | G12: 48.5 | H12: 49.3 | I12: 49 | J12: 48.5 | K12: 48.8 | L12: 65.5 | M12: =(D12+F12+H12)/3 -> 34.666667
A13: 36161 | C13: 54.9 | D13: 52.7 | E13: 52.6 | G13: 50 | H13: 47.3 | I13: 46.5 | J13: 45 | K13: 50.7 | L13: 63 | M13: =(D13+F13+H13)/3 -> 33.333333
... A50: 37288 | C50: 50.7 | D50: 49.9 | E50: 44.6 | G50: 48.5 | H50: 42.3 | I50: 46.5 | J50: 55 | K50: 55.9 | L50: 66.5 | M50: =(D50+F50+H50)/3 -> 30.733333
A51: 37316 | B51: 51.1 | C51: 49.8 | D51: 48.3 | E51: 44.3 | F51: 53 | G51: 47.5 | H51: 48.8 | I51: 45.5 | J51: 56.5 | K51: 55.3 | L51: 64.5 | M51: =(D51+F51+H51)/3 -> 50.033333
A52: 37347 | B52: 52.7 | C52: 57.5 | D52: 56.3 | E52: 43.9 | F52: 53 | G52: 51.5 | H52: 47.6 | I52: 47.5 | J52: 52.5 | K52: 54.3 | L52: 66.5 | M52: =(D52+F52+H52)/3 -> 52.3
A53: 37377 | B53: 52.8 | C53: 57.1 | D53: 56.4 | E53: 45.8 | F53: 52 | G53: 50 | H53: 49.2 | I53: 49.5 | J53: 49.5 | K53: 48.9 | L53: 65.5 | M53: =(D53+F53+H53)/3 -> 52.533333
A54: 37408 | B54: 53.5 | C54: 56.3 | D54: 58.4 | E54: 47.8 | F54: 51.5 | G54: 52.5 | H54: 53.7 | I54: 48.5 | J54: 52.5 | K54: 56.2 | L54: 63 | M54: =(D54+F54+H54)/3 -> 54.533333
A55: 37438 | B55: 54.8 | C55: 60.5 | D55: 57.3 | E55: 49.2 | F55: 52 | G55: 48.5 | H55: 55.2 | I55: 53.5 | J55: 61.5 | K55: 54 | L55: 65 | M55: =(D55+F55+H55)/3 -> 54.833333
A56: 37469 | B56: 52.5 | C56: 56.1 | D56: 56.4 | E56: 44 | F56: 53.5 | G56: 47.5 | H56: 53.1 | I56: 49 | J56: 57.5 | K56: 55.2 | L56: 66 | M56: =(D56+F56+H56)/3 -> 54.333333
A57: 37500 | B57: 50.4 | C57: 52.1 | D57: 50.7 | E57: 46.1 | F57: 52.5 | G57: 52 | H57: 60.5 | I57: 43.5 | J57: 59.5 | K57: 52.6 | L57: 66 | M57: =(D57+F57+H57)/3 -> 54.566667
A58: 37530 | B58: 50.9 | C58: 51.9 | D58: 51.6 | E58: 47.2 | F58: 53 | G58: 46 | H58: 55.1 | I58: 48 | J58: 46 | K58: 48.3 | L58: 62 | M58: =(D58+F58+H58)/3 -> 53.233333
A59: 37561 | B59: 52.3 | C59: 54.9 | D59: 54.8 | E59: 47.1 | F59: 52.5 | G59: 44.5 | H59: 53.4 | I59: 51 | J59: 57.5 | K59: 44.7 | L59: 66 | M59: =(D59+F59+H59)/3 -> 53.566667
A60: 37591 | B60: 51.4 | C60: 53.1 | D60: 52.3 | E60: 46.6 | F60: 53.5 | G60: 44 | H60: 56.1 | I60: 52 | J60: 49 | K60: 54.9 | L60: 64.5 | M60: =(D60+F60+H60)/3 -> 53.966667
A61: 37622 | B61: 52.9 | C61: 56.8 | D61: 56.4 | E61: 46 | F61: 52.5 | G61: 44 | H61: 57.6 | I61: 50.5 | J61: 58.5 | K61: 55.1 | L61: 61 | M61: =(D61+F61+H61)/3 -> 55.5
A62: 37653 | B62: 52.3 | C62: 55.5 | D62: 54.2 | E62: 47 | F62: 52.5 | G62: 45.5 | H62: 56.5 | I62: 51.5 | J62: 54 | K62: 51.8 | L62: 63 | M62: =(D62+F62+H62)/3 -> 54.4
... A343: 46204 | B343: 54 | C343: 55.4 | D343: 55.1 | E343: 51.2 | F343: 54.4 | G343: 51.2 | H343: 67.7 | I343: 54.9 | J343: 50.4 | K343: 49.4 | L343: 52.6 | M343: =(D343+F343+H343)/3 -> 59.066667

Sheet Stats
A1: Phrases | B1: Predictor
A2: ACC data
A3: accelerator
A4: activity is strong Yes
A5: acceleration of the category
A6: additional volume
A7: ahead of our expectations
A8: artificial intelligence
A9: big opportunity
A10: beginning to stabilize
A11: Bidding activity
A12: brand share
A13: continue to successfully
... A70: unprecedented demand

Sheet UK
A1: Date | B1: UK PMI | C1: UK NPMI | D1: UK GFK | E1: UK M2 | F1: UK IR | G1: UK CCPI | H1: UK M Approvals
A2: 26207 | F2: 5
A3: 26238 | F3: 5
A4: 26268 | F4: 5
A5: 26299 | F5: 5
A6: 26330 | F6: 5
A7: 26359 | F7: 5
A8: 26390 | F8: 5
A9: 26420 | F9: 5
A10: 26451 | F10: 5
A11: 26481 | F11: 6
A12: 26512 | F12: 6
A13: 26543 | F13: 6
... A123: 29891 | F123: 15
A124: 29921
A125: 29952 | D125: -22 | F125: 15
A126: 29983 | D126: -26 | F126: 14.5
A127: 30011 | D127: -19 | F127: 14
A128: 30042 | D128: -22 | F128: 13.5
A129: 30072 | D129: -18 | F129: 13
A130: 30103 | D130: -14 | F130: 13
A131: 30133 | D131: -5 | F131: 13
A132: 30164 | D132: -3 | F132: 12.5
A133: 30195 | D133: -8 | F133: 12
A134: 30225 | D134: -7 | F134: 10.5
A135: 30256 | D135: -9 | F135: 10.5
A136: 30286 | D136: -7 | F136: 9.5
... A168: 31260 | D168: -11 | F168: 12
A169: 31291 | D169: -10 | F169: 11.5 | H169: 120.8
A170: 31321 | D170: -12 | F170: 11.5 | H170: 115.8
A171: 31352 | D171: -9 | F171: 11.5 | H171: 120.8
A172: 31382 | D172: -7 | F172: 11.5 | H172: 118.4
A173: 31413 | D173: -7 | F173: 11.5 | H173: 111.4
A174: 31444 | D174: -7 | F174: 11.5 | H174: 115.4
A175: 31472 | D175: -11 | F175: 12.5 | H175: 116.2
A176: 31503 | D176: -14 | F176: 12.5 | H176: 111.2
A177: 31533 | D177: -11 | F177: 11.5 | H177: 115.2
A178: 31564 | D178: -8 | F178: 10.5 | H178: 118.3
A179: 31594 | D179: -8 | F179: 10 | H179: 122.3
A180: 31625 | D180: -6 | F180: 10 | H180: 127.3
...

Sheet SMB
A1: Date | B1: SMB | C1: SMB Employment | D1: SMB Capital | E1: SMB Inventories | F1: SMB Economy | G1: SMB Sales | H1: SMB FIJI | I1: SMB Construction | J1: SMB Manufacturing | K1: SMB Transportation | L1: SMB Wholesale | M1: SMB Retail | N1: Column1
A2: 31382 | B2: 100.285 | C2: 9 | D2: 31 | E2: 4 | F2: 11 | G2: 24 | H2: 15.8 | I2: 101.735 | J2: 101.279 | K2: 99.452 | L2: 100.548 | M2: 97.9
A3: 31413 | B3: 99.7915 | C3: 8 | D3: 29 | E3: 4 | F3: 13 | G3: 26 | H3: 16 | I3: 98.265 | J3: 102.466 | K3: 98.082 | L3: 103.379 | M3: 97.534
A4: 31444 | B4: 101.463 | C4: 14 | D4: 28 | E4: 3 | F4: 19 | G4: 25 | H4: 17.8 | I4: 102.648 | J4: 104.201 | K4: 95.982 | L4: 97.443 | M4: 100.183
A5: 31472 | B5: 101.015 | C5: 9 | D5: 32 | E5: 2 | F5: 17 | G5: 28 | H5: 17.6 | I5: 102.192 | J5: 102.831 | K5: 103.196 | L5: 100.731 | M5: 98.174
A6: 31503 | B6: 101.956 | C6: 9 | D6: 34 | E6: 6 | F6: 14 | G6: 27 | H6: 18 | I6: 101.644 | J6: 103.47 | K6: 101.461 | L6: 106.301 | M6: 98.995
A7: 31533 | B7: 101.289 | C7: 10 | D7: 30 | E7: 3 | F7: 17 | G7: 24 | H7: 16.8 | I7: 99.269 | J7: 103.014 | K7: 92.055 | L7: 104.932 | M7: 100.639
A8: 31564 | B8: 99.8372 | C8: 8 | D8: 31 | E8: 4 | F8: 9 | G8: 28 | H8: 16 | I8: 98.904 | J8: 103.196 | K8: 95.342 | L8: 98.447 | M8: 99.543
A9: 31594 | B9: 98.8144 | C9: 5 | D9: 30 | E9: -3 | F9: 10 | G9: 14 | H9: 11.2 | I9: 92.42 | J9: 97.169 | K9: 94.247 | L9: 98.539 | M9: 96.438
A10: 31625 | B10: 98.5861 | C10: 2 | D10: 31 | E10: 3 | F10: 6 | G10: 14 | H10: 11.2 | I10: 99.087 | J10: 99.087 | K10: 98.174 | L10: 95.525 | M10: 95.068
A11: 31656 | B11: 98.7596 | C11: 7 | D11: 30 | E11: 3 | F11: 7 | G11: 26 | H11: 14.6 | I11: 99.178 | J11: 102.466 | K11: 98.721 | L11: 99.635 | M11: 98.082
A12: 31686 | B12: 97.536 | C12: 6 | D12: 28 | E12: -5 | F12: 4 | G12: 28 | H12: 12.2 | I12: 99.543 | J12: 100.822 | K12: 103.653 | L12: 95.434 | M12: 94.886
A13: 31717 | B13: 100.668 | C13: 9 | D13: 29 | E13: 5 | F13: 4 | G13: 26 | H13: 14.6 | I13: 102.466 | J13: 101.37 | K13: 99.178 | L13: 93.242 | M13: 98.813
... A474: 45778 | B474: 98 | C474: 12 | D474: 22 | E474: -1 | F474: 25 | G474: 8 | H474: 13.2 | I474: 97.4 | J474: 96.35 | K474: 95.3 | L474: 97.28 | M474: 95.23
A475: 45809 | B475: 98.5 | C475: 14 | D475: 21 | E475: -1 | F475: 21 | G475: 7 | H475: =AVERAGE(SMB!$C475:$G475) -> 12.4 | I475: 99.63 | J475: 97.57 | K475: 94.13 | L475: 92.53 | M475: 92.69
A476: 45839 | B476: 100.6 | C476: 14 | D476: 22 | E476: 1 | F476: 36 | G476: 7 | H476: =AVERAGE(SMB!$C476:$G476) -> 16 | I476: 103.62 | J476: 106.62 | K476: 99.72 | L476: 106.4 | M476: 95.9
A477: 45870 | B477: 100.9 | C477: 15 | D477: 20 | E477: 0 | F477: 34 | G477: 11 | H477: =AVERAGE(SMB!$C477:$G477) -> 16 | I477: 104.71 | J477: 108.19 | K477: 100.9 | L477: 94.43 | M477: 96.22
A478: 45901 | B478: 98.3 | C478: 16 | D478: 20 | E478: 0 | F478: 22 | G478: 9 | H478: =AVERAGE(SMB!$C478:$G478) -> 13.4 | I478: 105 | J478: 97.02 | K478: 100.52 | L478: 94.81 | M478: 99.71
A479: 45931 | B479: 97.6 | C479: 15 | D479: 23 | E479: -3 | F479: 18 | G479: 6 | H479: =AVERAGE(SMB!$C479:$G479) -> 11.8 | I479: 106.14 | J479: 100.46 | K479: 101.86 | L479: 102.11 | M479: 95.08
A480: 45962 | B480: 98.48 | C480: 19 | D480: 21 | E480: -1 | F480: 13 | G480: 15 | H480: =AVERAGE(SMB!$C480:$G480) -> 13.4 | I480: 102.92 | J480: 101.69 | K480: 104.53 | L480: 100.28 | M480: 97.8
A481: 45992 | B481: 99.16 | C481: 17 | D481: 19 | E481: 0 | F481: 23 | G481: 9 | H481: =AVERAGE(SMB!$C481:$G481) -> 13.6 | I481: 103.87 | J481: 101.52 | K481: 104.56 | L481: 100.99 | M481: 94.07
A482: 46023 | B482: 98.66 | C482: 16 | D482: 18 | E482: -4 | F482: 22 | G482: 14 | H482: =AVERAGE(SMB!$C482:$G482) -> 13.2
A483: 46054 | B483: 98.73 | C483: 13 | D483: 17 | E483: -1 | F483: 20 | G483: 8 | H483: =AVERAGE(SMB!$C483:$G483) -> 11.4
A484: 46082 | B484: 96 | C484: 13 | D484: 17 | E484: -5 | F484: 13 | G484: 8 | H484: =AVERAGE(SMB!$C484:$G484) -> 9.2
A485: 46113 | B485: 95.5 | C485: 13 | D485: 17 | E485: -3 | F485: 5 | G485: 2 | H485: =AVERAGE(SMB!$C485:$G485) -> 6.8
A486: 46143 | B486: 94.4 | C486: 10 | D486: 16 | E486: -1 | F486: 2 | G486: 0 | H486: =AVERAGE(SMB!$C486:$G486) -> 5.4

Sheet EU
A1: Date | B1: EU PMI | C1: EU Consumer | D1: EU ZEW | E1: EU M2 Supply | F1: DE.ZEW | G1: Euro CBBS
A2: 34881 | F2: 6
A3: 34912 | C3: -5.9 | F3: 9.8
A4: 34943 | C4: -6.8 | E4: 3267552 | F4: 14.1
A5: 34973 | C5: -7.6 | E5: 3281956 | F5: 17.4
A6: 35004 | C6: -10.3 | E6: 3313101 | F6: 9.8
A7: 35034 | C7: -12 | E7: 3319905 | F7: -6.5
A8: 35065 | C8: -12.6 | E8: 3330302 | F8: -9.1
A9: 35096 | C9: -14.7 | E9: 3339988 | F9: 8.4
A10: 35125 | C10: -15.2 | E10: 3356999 | F10: 19.5
A11: 35156 | C11: -16.3 | E11: 3367104 | F11: 31.5
A12: 35186 | C12: -16.8 | E12: 3382092 | F12: 44.9
A13: 35217 | C13: -17.5 | E13: 3397417 | F13: 54.8
A14: 35247 | C14: -15.9 | E14: 3412004 | F14: 65.1
A15: 35278 | C15: -15.6 | E15: 3430951 | F15: 66.4
... A43: 36130 | C43: -4.1 | E43: 3932557 | F43: -17.9
A44: 36161 | C44: -2.4 | E44: 3906704 | F44: -24.9 | G44: 686308
A45: 36192 | C45: -3.7 | E45: 3932161 | F45: -25.1 | G45: 685553.75
A46: 36220 | C46: -2.1 | D46: -15.7 | E46: 3949151 | F46: -6.6 | G46: 689701.5
A47: 36251 | C47: -2.4 | D47: -1.4 | E47: 3969117 | F47: 9.2 | G47: 709898.4
A48: 36281 | C48: -3.9 | D48: 13 | E48: 3988198 | F48: 30.3 | G48: 693949
A49: 36312 | C49: -6.1 | D49: 30.5 | E49: 4024117 | F49: 45.1 | G49: 697723.5
A50: 36342 | C50: -5.8 | D50: 47.9 | E50: 4024149 | F50: 56.4 | G50: 725721.2
A51: 36373 | C51: -6 | D51: 59.9 | E51: 4030568 | F51: 74.3 | G51: 721642.25
A52: 36404 | C52: -4.2 | D52: 75.4 | E52: 4051137 | F52: 74 | G52: 723728
A53: 36434 | C53: -4.7 | D53: 77.9 | E53: 4066546 | F53: 80.7 | G53: 727391.4
A54: 36465 | C54: -4.3 | D54: 79.9 | E54: 4076755 | F54: 82.4 | G54: 737370.5
A55: 36495 | C55: -3 | D55: 83.4 | E55: 4123296 | F55: 84.5 | G55: 765795.8
A56: 36526 | C56: -2.5 | D56: 87.9 | E56: 4137864 | F56: 84.4 | G56: 761593.72
A57: 36557 | C57: -2 | D57: 86.3 | E57: 4148364 | F57: 89.6 | G57: 757490.52
... A145: 39234 | C145: -4.5 | D145: 10.7 | E145: 7061036 | F145: 24 | G145: 1186034
A146: 39264 | B146: 55.6 | C146: -1.5 | D146: 22.3 | E146: 7097722 | F146: 20.3 | G146: 1196531
A147: 39295 | B147: 54.9 | C147: -2 | D147: 19 | E147: 7153554 | F147: 10.4 | G147: 1206068.4
A148: 39326 | B148: 54.3 | C148: -2 | D148: 7.2 | E148: 7273698 | F148: -6.9 | G148: 1236667.2
A149: 39356 | B149: 53.2 | C149: -4.4 | D149: -6.1 | E149: 7317747 | F149: -18.1 | G149: 1257575.2
A150: 39387 | B150: 51.5 | C150: -6.4 | D150: -20.3 | E150: 7360271 | F150: -18.1 | G150: 1271856.6
A151: 39417 | B151: 52.8 | C151: -7.2 | D151: -19 | E151: 7445003 | F151: -32.5 | G151: 1403912.2
A152: 39448 | B152: 52.6 | C152: -9.3 | D152: -30 | E152: 7504620 | F152: -37.2 | G152: 1321293.2
A153: 39479 | B153: 52.8 | C153: -9.6 | D153: -35.7 | E153: 7539505 | F153: -41.6 | G153: 1336580.6
A154: 39508 | B154: 52.3 | C154: -11.5 | D154: -41.7 | E154: 7619314 | F154: -39.5 | G154: 1367603.2
...

Sheet Links
B1: ISM (Institute for Supply Management)
A2: Europe PMI | B2: Euro Area Manufacturing PMI
A3: Europe Service Pmi | B3: Euro Area Services PMI
A4: CC | B4: Euro Area Consumer Confidence
A5: ZEW | B5: https://tradingeconomics.com/euro-area/zew-economic-sentiment-index
A6: M2 | B6: Euro Area Money Supply M2
A7: Monthly | B7: Germany ZEW Economic Sentiment Index
A8: PMI | B8: United Kingdom Manufacturing PMI
A9: NPMI | B9: United Kingdom Services PMI
A10: GFK | B10: United Kingdom Consumer Confidence
A11: M2 | B11: United Kingdom Money Supply M2
A12: IR | B12: United Kingdom Interest Rate
A13: CCPI | B13: United Kingdom Core Consumer Prices
A14: PPI
A15: Mort App | B15: United Kingdom Mortgage Approvals
A16: Monthly | B16: https://www.marketwatch.com/investing/future/gc00/download-data?startDate=1/15/2018&endDate=04/14/2023
A17: SMB | B17: Small Business Optimism Index
